2024-06-03 23:02:58,727 - easyeditor.editors.editor - INFO - Instantiating model
06/03/2024 23:02:58 - INFO - easyeditor.editors.editor -   Instantiating model
/home/bingxing2/home/scx7avs/lyc/EasyEdit/nltk_data
['/home/bingxing2/home/scx7avs/nltk_data', '/home/bingxing2/home/scx7avs/anaconda3/envs/ke/nltk_data', '/home/bingxing2/home/scx7avs/anaconda3/envs/ke/share/nltk_data', '/home/bingxing2/home/scx7avs/anaconda3/envs/ke/lib/nltk_data', '/usr/share/nltk_data', '/usr/local/share/nltk_data', '/usr/lib/nltk_data', '/usr/local/lib/nltk_data', '/home/bingxing2/home/scx7avs/lyc/EasyEdit/nltk_data']
./Llama-3-8B_recent_pre_edit.json
Using Huggingface cache: /mnt/xzk/Llama-3-8B
Traceback (most recent call last):
  File "/home/bingxing2/home/scx7avs/anaconda3/envs/ke/lib/python3.9/site-packages/transformers/utils/hub.py", line 398, in cached_file
    resolved_file = hf_hub_download(
  File "/home/bingxing2/home/scx7avs/.local/lib/python3.9/site-packages/huggingface_hub/utils/_validators.py", line 106, in _inner_fn
    validate_repo_id(arg_value)
  File "/home/bingxing2/home/scx7avs/.local/lib/python3.9/site-packages/huggingface_hub/utils/_validators.py", line 154, in validate_repo_id
    raise HFValidationError(
huggingface_hub.errors.HFValidationError: Repo id must be in the form 'repo_name' or 'namespace/repo_name': '/mnt/xzk/Llama-3-8B'. Use `repo_type` argument if needed.

The above exception was the direct cause of the following exception:

Traceback (most recent call last):
  File "/home/bingxing2/home/scx7avs/lyc/EasyEdit/examples/run_knowedit_llama2.py", line 207, in <module>
    editor = BaseEditor.from_hparams(hparams)
  File "/home/bingxing2/home/scx7avs/lyc/EasyEdit/easyeditor/editors/editor.py", line 53, in from_hparams
    return cls(hparams)
  File "/home/bingxing2/home/scx7avs/lyc/EasyEdit/easyeditor/editors/editor.py", line 88, in __init__
    self.model = AutoModelForCausalLM.from_pretrained(self.model_name, torch_dtype=torch_dtype, device_map=device_map)
  File "/home/bingxing2/home/scx7avs/anaconda3/envs/ke/lib/python3.9/site-packages/transformers/models/auto/auto_factory.py", line 484, in from_pretrained
    resolved_config_file = cached_file(
  File "/home/bingxing2/home/scx7avs/anaconda3/envs/ke/lib/python3.9/site-packages/transformers/utils/hub.py", line 462, in cached_file
    raise EnvironmentError(
OSError: Incorrect path_or_model_id: '/mnt/xzk/Llama-3-8B'. Please provide either the path to a local folder or the repo_id of a model on the Hub.
